Workbook

Sheet (D) Summary
A1: (D) PIPE MOULDS SUMMARY — JUNE 2026
A2: Prayag — Kehrani (KH) plant | Injection-moulding, mould-wise view | Output in KG
A4: Material | B4: Moulds Listed | C4: Moulds Run | D4: Production (Pcs) | E4: Production (KG) | F4: Mould Utilisation (Hrs) | G4: Avg KG / Mould Run | H4: Share of KG
A5: CPVC | B5: =COUNTA(CPVC!B5:B84) -> 80 | C5: =COUNTIF(CPVC!G5:G84,">0") -> 67 | D5: =CPVC!G85 -> 716595 | E5: =CPVC!H85 -> 19591.32 | F5: =CPVC!J85 -> 2390.7 | G5: =IFERROR(E5/C5,0) -> 292.40776 | H5: =IFERROR(E5/$E$9,0) -> 0.21975253
A6: UPVC | B6: =COUNTA(UPVC!B5:B105) -> 101 | C6: =COUNTIF(UPVC!G5:G105,">0") -> 85 | D6: =UPVC!G106 -> 454396 | E6: =UPVC!H106 -> 27796.29 | F6: =UPVC!J106 -> 2749.99 | G6: =IFERROR(E6/C6,0) -> 327.01518 | H6: =IFERROR(E6/$E$9,0) -> 0.31178629
A7: SWR | B7: =COUNTA(SWR!B5:B52) -> 48 | C7: =COUNTIF(SWR!G5:G52,">0") -> 47 | D7: =SWR!G53 -> 129531 | E7: =SWR!H53 -> 33177.94 | F7: =SWR!J53 -> 2954.86 | G7: =IFERROR(E7/C7,0) -> 705.91362 | H7: =IFERROR(E7/$E$9,0) -> 0.37215135
A8: AGRI | B8: =COUNTA(AGRI!B5:B48) -> 44 | C8: =COUNTIF(AGRI!G5:G48,">0") -> 31 | D8: =AGRI!G49 -> 39595 | E8: =AGRI!H49 -> 8586.19 | F8: =AGRI!J49 -> 672.93 | G8: =IFERROR(E8/C8,0) -> 276.97387 | H8: =IFERROR(E8/$E$9,0) -> 0.096309842
A9: TOTAL | B9: =SUM(B5:B8) -> 273 | C9: =SUM(C5:C8) -> 230 | D9: =SUM(D5:D8) -> 1340117 | E9: =SUM(E5:E8) -> 89151.74 | F9: =SUM(F5:F8) -> 8768.48 | G9: =IFERROR(E9/C9,0) -> 387.61626 | H9: =IFERROR(E9/$E$9,0) -> 1
A12: Notes & data provenance
A13: • Source: mould-wise working reports (Report-17 CPVC / 18 UPVC / 19 SWR / 20 AGRI) inside the June'26 Pipe & Fitting workbook.
A14: • Those tabs carry a stale 'APRIL'26' header row; the figures are June 2026. Confirmed by tie-out below.
A15: • Reconciliation: mould-wise total = 89,152 KG vs machine-wise Report-12 (June) = 89,100 KG — a 0.06% difference. Grand totals tie; per-material splits differ by design (Report-12 tags by item material and carries small PP/PPR/ABS lines; mould reports tag by mould family).
A16: • 'Moulds Listed' = mould codes present in the source tab; 'Moulds Run' = moulds with production > 0 (matches the (D) final report's 'No. of Mould Run': 67/85/47/31).
A17: • Every figure recomputed from source cells; no value copied from the final/summary report. All totals are live Excel formulas.

Sheet CPVC
A1: (D) Pipe Moulds Summary — CPVC Mould Working Report | June 2026
A2: Source: Report-17 (mould-wise), Jun'26 workbook. Tab header reads 'APRIL'26' (stale); data validated as June — see Summary notes.
A4: S.No. | B4: Mould Code | C4: Mould Cavity | D4: Cycle Time / Pc | E4: PC Weight (g) | F4: Runner Weight (g) | G4: Production (Pcs) | H4: Production (KG) | I4: Wt. of Total Prod. (KG) | J4: Mould Utilisation (Hrs)
A5: 1 | B5: 33000778 | C5: 2 | D5: 89 | E5: 66.5 | F5: 16.3 | G5: 870 | H5: 57.86 | I5: 68.3 | J5: 21.51
A6: 2 | B6: C62 | C6: 16 | D6: 6.6875 | E6: 29 | F6: 10.25 | G6: 50300 | H6: 1458.7 | I6: 1458.7 | J6: 93.44
A7: 3 | B7: C532 | C7: 6 | D7: 13.333333 | E7: 30.25 | F7: 10.666667 | G7: 7500 | H7: 226.88 | I7: 226.88 | J7: 27.78
A8: 4 | B8: C12 | C8: 2 | D8: 52.5 | E8: 86 | F8: 39.8 | G8: 3440 | H8: 291.71 | I8: 291.71 | J8: 50.17
A9: 5 | B9: C521 | C9: 8 | D9: 14.625 | E9: 30 | F9: 7.875 | G9: 48550 | H9: 1456.5 | I9: 2378.95 | J9: 197.23
A10: 6 | B10: PP1 | C10: 16 | D10: 7.8125 | E10: 15.35 | F10: 4.625 | G10: 111240 | H10: 1707.53 | I10: 1707.53 | J10: 241.41
A11: 7 | B11: C65 | C11: 4 | D11: 32.075 | E11: 145.45 | F11: 12.125 | G11: 5450 | H11: 792.7 | I11: 792.7 | J11: 48.56
A12: 8 | B12: C92 | C12: 4 | D12: 20 | E12: 18.5 | F12: 13.875 | G12: 3850 | H12: 71.23 | I12: 71.23 | J12: 21.39
A13: 9 | B13: C272CN | C13: 4 | D13: 27.25 | E13: 28.75 | F13: 6.5 | G13: 2300 | H13: 66.13 | I13: 66.13 | J13: 17.41
A14: 10 | B14: C23BD | C14: 4 | D14: 44.5 | E14: 92.5 | F14: 12.275 | G14: 10000 | H14: 925.01 | I14: 925 | J14: 123.61
A15: 11 | B15: C504 | C15: 4 | D15: 25.25 | E15: 46 | F15: 17.5 | G15: 2530 | H15: 116.38 | I15: 116.38 | J15: 17.75
A16: 12 | B16: C273TCN | C16: 2 | D16: 42.5 | E16: 49.5 | F16: 30.25 | G16: 4820 | H16: 238.6 | I16: 238.59 | J16: 56.9
... A47: 43 | B47: C930 | C47: 4 | D47: 27.75 | E47: 30 | F47: 9.375 | G47: 1305 | H47: 39.8 | I47: 62.64 | J47: 10.06
A48: 44 | B48: PC3 | E48: 2.12 | G48: 6500 | H48: 13.72 | I48: 13.72 | J48: 13.77
A49: 45 | B49: C46 | C49: 4 | D49: 28.25 | E49: 133 | F49: 9.5 | G49: 3010 | H49: 400.33 | I49: 400.33 | J49: 23.62
A50: 46 | B50: C702 | C50: 9 | D50: 12.777778 | E50: 29.3 | F50: 7.0655556 | G50: 9500 | H50: 278.35 | I50: 278.35 | J50: 33.72
A51: 47 | B51: C322 | C51: 8 | D51: 14.5 | E51: 37 | F51: 7.6875 | G51: 9713 | H51: 359.38 | I51: 543.93 | J51: 39.12
A52: 48 | B52: C25LH | C52: 2 | D52: 68 | E52: 27.5 | F52: 4.5 | G52: 660 | H52: 18.15 | I52: 18.15 | J52: 12.47
A53: 49 | B53: C26LH | C53: 2 | D53: 69 | E53: 38.65 | F53: 4.5 | G53: 660 | H53: 25.51 | I53: 25.51 | J53: 12.65
A54: 50 | B54: C523 | C54: 8 | D54: 14.125 | E54: 38 | F54: 5.9375 | G54: 4966 | H54: 178.78 | I54: 273.13 | J54: 19.48
A55: 51 | B55: C23H | C55: 8 | D55: 14.75 | E55: 19 | F55: 3.8125 | G55: 7000 | H55: 133 | I55: 133 | J55: 28.68
A56: 52 | B56: C44 | C56: 8 | D56: 12.625 | E56: 36.4 | F56: 8.6375 | G56: 5475 | H56: 199.29 | I56: 199.29 | J56: 19.2
A57: 53 | B57: C24BA | C57: 4 | D57: 32.5 | E57: 50 | F57: 16.125 | G57: 2660 | H57: 133 | I57: 133 | J57: 24.01
A58: 54 | B58: C93 | C58: 8 | D58: 18 | E58: 32 | F58: 8.1625 | G58: 5975 | H58: 190.9 | I58: 190.9 | J58: 29.88
A59: 55 | B59: C42 | C59: 16 | D59: 5.75 | E59: 13.5 | F59: 5 | G59: 33000 | H59: 445.5 | I59: 445.5 | J59: 52.71
A60: 56 | B60: C25BA | C60: 4 | D60: 34 | E60: 73 | F60: 15 | G60: 805 | H60: 58.77 | I60: 58.77 | J60: 7.6
... A71: 67 | B71: C22ST | C71: 8 | D71: 8.75 | E71: 4.6 | F71: 4.1625 | G71: 2950 | H71: 13.57 | I71: 13.57 | J71: 7.17
A72: 68 | B72: U11 | C72: 1 | D72: 143 | E72: 58.8 | F72: 29.1
A73: 69 | B73: CM21S | C73: 1 | D73: 80 | E73: 65 | F73: 21
A74: 70 | B74: C66 | C74: 4 | D74: 33.75 | E74: 262 | F74: 11.625
A75: 71 | B75: C605 | C75: 6 | D75: 15.5 | E75: 41 | F75: 10.266667
A76: 72 | B76: C32P | C76: 16 | D76: 6.5625 | E76: 15.22 | F76: 9.6
A77: 73 | B77: C12 | C77: 2 | D77: 52.5 | E77: 86 | F77: 39.8
A78: 74 | B78: PP1 | C78: 16 | D78: 7.8125 | E78: 15.35 | F78: 4.625
A79: 75 | B79: C22TR | C79: 8 | D79: 6.25 | E79: 0.68 | F79: 0.9375
A80: 76 | B80: CM21S | C80: 1 | D80: 80 | E80: 65 | F80: 21
A81: 77 | B81: C53 | C81: 16 | D81: 8.625 | E81: 36.3 | F81: 11.46875
...

Sheet UPVC
A1: (D) Pipe Moulds Summary — UPVC Mould Working Report | June 2026
A2: Source: Report-18 (mould-wise), Jun'26 workbook. Tab header reads 'APRIL'26' (stale); data validated as June — see Summary notes.
A4: S.No. | B4: Mould Code | C4: Mould Cavity | D4: Cycle Time / Pc | E4: PC Weight (g) | F4: Runner Weight (g) | G4: Production (Pcs) | H4: Production (KG) | I4: Wt. of Total Prod. (KG) | J4: Mould Utilisation (Hrs)
A5: 1 | B5: U531 | C5: 4 | D5: 25 | E5: 61.3 | F5: 11.7125 | G5: 1275 | H5: 78.16 | I5: 78.16 | J5: 8.85
A6: 2 | B6: U602 | C6: 16 | D6: 5 | E6: 18 | F6: 3.7125 | G6: 9200 | H6: 165.6 | I6: 165.6 | J6: 12.78
A7: 3 | B7: U54 | C7: 6 | D7: 30.833333 | E7: 113 | F7: 9.5 | G7: 10040 | H7: 1117.46 | I7: 1117.45 | J7: 85.99
A8: 4 | B8: U43 | C8: 8 | D8: 14.5 | E8: 48 | F8: 8.75 | G8: 49500 | H8: 2376 | I8: 2376 | J8: 199.38
A9: 5 | B9: U63 | C9: 8 | D9: 19.375 | E9: 94 | F9: 8.8125 | G9: 18675 | H9: 1755.45 | I9: 1755.45 | J9: 97.91
A10: 6 | B10: U33M | C10: 4 | D10: 33.5 | E10: 43.45 | F10: 20.6125 | G10: 9320 | H10: 404.95 | I10: 404.95 | J10: 86.73
A11: 7 | B11: U14 | C11: 2 | D11: 92.5 | E11: 267 | F11: 49 | G11: 920 | H11: 245.64 | I11: 245.64 | J11: 23.64
A12: 8 | B12: U55 | C12: 4 | D12: 38.75 | E12: 148 | F12: 8.5 | G12: 10190 | H12: 1492.84 | I12: 1492.84 | J12: 102.61
A13: 9 | B13: U71 | C13: 8 | D13: 17.75 | E13: 29.325 | F13: 8.125 | G13: 3569 | H13: 104.66 | I13: 248.76 | J13: 17.6
A14: 10 | B14: U81 | C14: 8 | D14: 15 | E14: 27 | F14: 7.5875 | G14: 5741 | H14: 152.85 | I14: 253.32 | J14: 23.92
A15: 11 | B15: U74 | C15: 2 | D15: 76 | E15: 73.15 | F15: 16.7 | G15: 1247 | H15: 91.22 | I15: 284.94 | J15: 26.33
A16: 12 | B16: U821 | C16: 12 | D16: 5.8333333 | E16: 10 | F16: 5.0833333 | G16: 5600 | H16: 54.88 | I16: 54.88 | J16: 9.07
... A89: 85 | B89: U12 | C89: 1 | D89: 143 | E89: 103.5 | F89: 29.1 | G89: 300 | H89: 31.05 | I89: 31.05 | J89: 11.92
A90: 86 | B90: U275CN | C90: 4 | D90: 29.5 | E90: 34 | F90: 8.25
A91: 87 | B91: U11 | C91: 1 | D91: 143 | E91: 58.8 | F91: 29.1
A92: 88 | B92: U12 | C92: 1 | D92: 143 | E92: 103.5 | F92: 29.1
A93: 89 | B93: U251 | C93: 4 | D93: 43 | E93: 165 | F93: 8.75
A94: 90 | B94: U275TC | C94: 2 | D94: 57.5 | E94: 97 | F94: 15.75
A95: 91 | B95: U242 | C95: 4 | D95: 28 | E95: 130.8 | F95: 13.025
A96: 92 | B96: U504 | C96: 4 | D96: 30 | E96: 99 | F96: 10.75
A97: 93 | B97: U731 | C97: 4 | D97: 28.045 | E97: 42 | F97: 8.4375
A98: 94 | B98: U33F | C98: 4 | D98: 26 | E98: 30.45 | F98: 7.75
A99: 95 | B99: U45 | C99: 4 | D99: 25.25 | E99: 92 | F99: 8.0875
A100: 96 | B100: U46 | C100: 4 | D100: 41 | E100: 133.85 | F100: 10.7
A101: 97 | B101: U91 | C101: 8 | D101: 12.25 | E101: 20.55 | F101: 6.75
... A105: 101 | B105: U41 | C105: 12 | D105: 9.4166667 | E105: 21 | F105: 6.5916667
A106: TOTAL | G106: =SUM(G5:G105) -> 454396 | H106: =SUM(H5:H105) -> 27796.29 | I106: =SUM(I5:I105) -> 29983.37 | J106: =SUM(J5:J105) -> 2749.99

Sheet SWR
A1: (D) Pipe Moulds Summary — SWR Mould Working Report | June 2026
A2: Source: Report-19 (mould-wise), Jun'26 workbook. Tab header reads 'APRIL'26' (stale); data validated as June — see Summary notes.
A4: S.No. | B4: Mould Code | C4: Mould Cavity | D4: Cycle Time / Pc | E4: PC Weight (g) | F4: Runner Weight (g) | G4: Production (Pcs) | H4: Production (KG) | I4: Wt. of Total Prod. (KG) | J4: Mould Utilisation (Hrs)
A5: 1 | B5: 5762 | C5: 4 | D5: 24.5 | E5: 43.5 | F5: 8.5 | G5: 19400 | H5: 820.62 | I5: 820.62 | J5: 132.03
A6: 2 | B6: 5710S | C6: 2 | D6: 62.5 | E6: 141 | F6: 16.4 | G6: 2610 | H6: 368.01 | I6: 368.01 | J6: 45.31
A7: 3 | B7: 90000016 | C7: 1 | D7: 128 | E7: 483 | F7: 39 | G7: 630 | H7: 302.4 | I7: 302.4 | J7: 22.4
A8: 4 | B8: 5121 | C8: 2 | D8: 71.5 | E8: 289 | F8: 23 | G8: 1188 | H8: 333.83 | I8: 333.83 | J8: 23.6
A9: 5 | B9: 5110 | C9: 1 | D9: 116 | E9: 346 | F9: 42 | G9: 3900 | H9: 1302.6 | I9: 1302.6 | J9: 125.67
A10: 6 | B10: 5733 | C10: 1 | D10: 114 | E10: 275 | F10: 42 | G10: 8070 | H10: 2154.69 | I10: 2154.69 | J10: 255.55
A11: 7 | B11: 5111 | C11: 2 | D11: 62.5 | E11: 399 | F11: 31.5 | G11: 16270 | H11: 6491.73 | I11: 6491.73 | J11: 282.47
A12: 8 | B12: 5133 | C12: 1 | D12: 170 | E12: 555 | F12: 35 | G12: 8175 | H12: 4349.1 | I12: 4349.1 | J12: 386.04
A13: 9 | B13: 5763W | C13: 1 | D13: 90 | E13: 296 | G13: 2808 | H13: 831.18 | I13: 831.17 | J13: 70.2
A14: 10 | B14: 5157 | C14: 1 | D14: 120 | E14: 225.3 | F14: 41 | G14: 3300 | H14: 743.49 | I14: 743.49 | J14: 110
A15: 11 | B15: 5792S | C15: 2 | D15: 61 | E15: 45 | F15: 8 | G15: 1190 | H15: 53.55 | I15: 53.55 | J15: 20.16
A16: 12 | B16: 5712 | C16: 1 | D16: 116 | E16: 205 | F16: 40 | G16: 5650 | H16: 1113.05 | I16: 1113.05 | J16: 182.06
A17: 13 | B17: 5112S | C17: 1 | D17: 121 | E17: 344 | F17: 32 | G17: 1358 | H17: 467.15 | I17: 467.15 | J17: 45.64
A18: 14 | B18: 5142S | C18: 1 | D18: 184 | E18: 614 | F18: 28 | G18: 408 | H18: 250.51 | I18: 250.51 | J18: 20.85
A19: 15 | B19: 5710 | C19: 1 | D19: 118 | E19: 174 | F19: 33.5 | G19: 5550 | H19: 937.99 | I19: 937.95 | J19: 181.92
A20: 16 | B20: 5112 | C20: 1 | D20: 129 | E20: 432 | F20: 43.3 | G20: 3852 | H20: 1573.57 | I20: 1573.54 | J20: 138.03
A21: 17 | B21: 5164 | C21: 2 | D21: 45 | E21: 85 | F21: 9 | G21: 5408 | H21: 445.09 | I21: 445.08 | J21: 67.6
A22: 18 | B22: 5912S | C22: 1 | D22: 122 | E22: 232 | F22: 26.5 | G22: 420 | H22: 97.44 | I22: 97.44 | J22: 14.23
A23: 19 | B23: 5711S | C23: 1 | D23: 102 | E23: 165 | F23: 25 | G23: 1260 | H23: 207.9 | I23: 207.9 | J23: 35.7
A24: 20 | B24: 5111S | C24: 1 | D24: 103 | E24: 330 | F24: 30 | G24: 1225 | H24: 400.58 | I24: 400.58 | J24: 35.05
A25: 21 | B25: 5133S | C25: 1 | D25: 110 | E25: 452.5 | F25: 28.5 | G25: 675 | H25: 305.45 | I25: 305.44 | J25: 20.63
... A51: 47 | B51: 5910S | C51: 2 | D51: 60.5 | E51: 190 | F51: 17.5 | G51: 900 | H51: 171 | I51: 171 | J51: 15.13
A52: 48 | B52: 5134 | C52: 1 | D52: 175 | E52: 543 | F52: 43
A53: TOTAL | G53: =SUM(G5:G52) -> 129531 | H53: =SUM(H5:H52) -> 33177.94 | I53: =SUM(I5:I52) -> 33177.83 | J53: =SUM(J5:J52) -> 2954.86

Sheet AGRI
A1: (D) Pipe Moulds Summary — AGRI Mould Working Report | June 2026
A2: Source: Report-20 (mould-wise), Jun'26 workbook. Tab header reads 'APRIL'26' (stale); data validated as June — see Summary notes.
A4: S.No. | B4: Mould Code | C4: Mould Cavity | D4: Cycle Time / Pc | E4: PC Weight (g) | F4: Runner Weight (g) | G4: Production (Pcs) | H4: Production (KG) | I4: Wt. of Total Prod. (KG) | J4: Mould Utilisation (Hrs)
A5: 1 | B5: AS449 | C5: 1 | D5: 128 | E5: 463 | F5: 10 | G5: 475 | H5: 219.93 | I5: 219.93 | J5: 16.89
A6: 2 | B6: A449 | C6: 1 | D6: 140 | E6: 463 | F6: 10 | G6: 3675 | H6: 1701.55 | I6: 1701.53 | J6: 130.67
A7: 3 | B7: AS249 | C7: 0 | G7: 350 | H7: 84.7 | I7: 84.7 | J7: 9.82
A8: 4 | B8: A549 | C8: 1 | D8: 95 | E8: 174 | F8: 5 | G8: 2975 | H8: 487.9 | I8: 487.9 | J8: 78.51
A9: 5 | B9: A369 | C9: 1 | D9: 185 | E9: 725 | F9: 9 | G9: 1110 | H9: 804.76 | I9: 804.75 | J9: 57.04
A10: 6 | B10: A269 | C10: 1 | D10: 90 | E10: 295.6 | F10: 38 | G10: 650 | H10: 192.14 | I10: 192.14 | J10: 16.25
A11: 7 | B11: A565 | C11: 4 | D11: 20.5 | E11: 40 | F11: 7 | G11: 2000 | H11: 80 | I11: 80 | J11: 11.39
A12: 8 | B12: A464 | C12: 8 | D12: 16.875 | E12: 61.5 | F12: 8.375 | G12: 4250 | H12: 261.38 | I12: 261.38 | J12: 19.92
A13: 9 | B13: A547 | C13: 2 | D13: 50 | E13: 78 | F13: 16.5 | G13: 450 | H13: 35.1 | I13: 35.1 | J13: 6.25
A14: 10 | B14: A465 | C14: 4 | D14: 30 | E14: 97.5 | F14: 12.125 | G14: 7000 | H14: 682.5 | I14: 682.5 | J14: 58.33
A15: 11 | B15: A469 | C15: 1 | D15: 100 | E15: 533 | F15: 8.7 | G15: 792 | H15: 422.14 | I15: 422.14 | J15: 22
A16: 12 | B16: A346 | C16: 2 | D16: 45 | E16: 181 | F16: 17.5 | G16: 1200 | H16: 217.2 | I16: 217.2 | J16: 15
A17: 13 | B17: A467 | C17: 2 | D17: 39 | E17: 232.8 | F17: 22 | G17: 2310 | H17: 537.77 | I17: 537.77 | J17: 25.03
A18: 14 | B18: A348 | C18: 2 | D18: 64 | E18: 398 | F18: 20.5 | G18: 672 | H18: 266.78 | I18: 266.78 | J18: 11.95
A19: 15 | B19: A447 | C19: 2 | D19: 44 | E19: 192 | F19: 19.3 | G19: 3220 | H19: 618.24 | I19: 618.24 | J19: 39.36
... A32: 28 | B32: A248 | C32: 2 | D32: 41.5 | E32: 155 | F32: 17.5 | G32: 750 | H32: 116.25 | I32: 116.25 | J32: 8.65
A33: 29 | B33: A714 | C33: 0 | G33: 480 | H33: 19.68 | I33: 19.68 | J33: 7
A34: 30 | B34: A717 | C34: 0 | G34: 480 | H34: 21.6 | I34: 21.6 | J34: 7
A35: 31 | B35: A719 | C35: 0 | G35: 600 | H35: 26.4 | I35: 26.4 | J35: 8.75
A36: 32 | B36: A718 | C36: 0
A37: 33 | B37: AS348 | C37: 2 | D37: 128 | E37: 397 | F37: 20.5
A38: 34 | B38: A212 | C38: 0
A39: 35 | B39: A504 | C39: 2 | D39: 42 | E39: 120 | F39: 24.5
A40: 36 | B40: A503 | C40: 2 | D40: 39 | E40: 70 | F40: 22.5
A41: 37 | B41: A369 | C41: 1 | D41: 185 | E41: 725 | F41: 9
A42: 38 | B42: A469 | C42: 1 | D42: 100 | E42: 533 | F42: 8.7
A43: 39 | B43: A364 | C43: 8 | D43: 11.625 | E43: 78.9 | F43: 9.5625
A44: 40 | B44: A213 | C44: 0
A45: 41 | B45: A549 | C45: 1 | D45: 95 | E45: 174 | F45: 5
A46: 42 | B46: A767 | C46: 1 | D46: 115 | E46: 236 | F46: 30
A47: 43 | B47: A666 | C47: 1 | D47: 118 | E47: 552 | F47: 8
A48: 44 | B48: A665 | C48: 1 | D48: 124 | E48: 507.5 | F48: 8
A49: TOTAL | G49: =SUM(G5:G48) -> 39595 | H49: =SUM(H5:H48) -> 8586.19 | I49: =SUM(I5:I48) -> 8586.16 | J49: =SUM(J5:J48) -> 672.93
